Workbook

Sheet How to use
A1: Feature price review
A3: Why this exists
A4: The Learn screen's Features tab needs a price and requirements for every feature in the compendium. 99 features matched the rules workbook (Odbornosti) automatically; they are listed on the Auto-accepted sheet for a spot check. The 124 on the Review sheet did not, and need your decision.
A6: What to fill in (yellow columns on the Review sheet)
A7: Decision: pick one from the dropdown.
A8: Accept = use the suggested book row (column D).
A9: Use row = use the book row number you type in column I (find numbers on the Book rows sheet).
A10: Manual = no book row fits; type the price in J, currency in K and requirements in L.
A11: Not buyable = leave this feature out of the Available list.
A12: Requirements (L): write them the way the book does, Czech is fine, clauses separated by ; and alternatives by /. Example: Akrobacie V; Souboj V / Střelba V
A13: Notes (M): anything I should know, e.g. "rename the item to match the book".
A15: Pre-filled rows
... A20: Example (a filled-in row, not part of the data)
A21: Pack feature | B21: Decision | C21: Book row # (if Use row) | D21: Manual cost | E21: Manual currency | F21: Manual requirements | G21: Notes
A22: Polearm master | B22: Manual | D22: 5 | E22: CP | F22: Dřevcové VI; Učitel I | G22: Book has Dřevcový mistr at row 44, but that one needs no teacher

Sheet Review
A1: Pack feature (English) | B1: Czech name | C1: Pack folder | D1: Suggested book row # | E1: Suggested book name | F1: Why suggested | G1: Other candidates | H1: Decision | I1: Book row # (if Use row) | J1: Manual cost | K1: Manual currency | L1: Manual requirements | M1: Notes | N1: Resolved row # | O1: Resolved cost | P1: Resolved currency | Q1: Resolved requirements
A2: Acrobatic defense | B2: Akrobatická obrana | C2: Features / Combat features | D2: 20 | E2: Akrobatická obrana I | F2: Book has tiers (I, II...) but the pack has one item; tier I suggested | G2: r22 Akrobatická obrana II (0.92); r24 Akrobatická obrana III (0.90); r26 Akrobat I (0.59); r338 Plošná obrana (0.58) | N2: =IF(H2="Accept",D2,IF(H2="Use row",I2,"")) | O2: =IF(H2="Manual",IF(J2="","",J2),IF(N2="","",IFERROR(INDEX('Book rows'!$D$2:$D$392,MATCH(N2,'Book rows'!$A$2:$A$392,0)),"row not found"))) | P2: =IF(H2="Manual",IF(K2="","",K2),IF(N2="","",IFERROR(INDEX('Book rows'!$E$2:$E$392,MATCH(N2,'Book rows'!$A$2:$A$392,0)),"row not found"))) | Q2: =IF(H2="Manual",IF(L2="","",L2),IF(N2="","",IFERROR(INDEX('Book rows'!$F$2:$F$392,MATCH(N2,'Book rows'!$A$2:$A$392,0)),"row not found")))
A3: Adept: Combat | B3: Adept: Souboj | C3: Features / Combat features | D3: 14 | E3: Adept boje | F3: Same feature: the book calls it Adept boje | G3: r16 Expert boje (0.61); r166 Zákeřný boj (0.52); r314 Adept Magie (0.52); r267 Spolubojovník (0.48) | H3: Accept | N3: =IF(H3="Accept",D3,IF(H3="Use row",I3,"")) | O3: =IF(H3="Manual",IF(J3="","",J3),IF(N3="","",IFERROR(INDEX('Book rows'!$D$2:$D$392,MATCH(N3,'Book rows'!$A$2:$A$392,0)),"row not found"))) | P3: =IF(H3="Manual",IF(K3="","",K3),IF(N3="","",IFERROR(INDEX('Book rows'!$E$2:$E$392,MATCH(N3,'Book rows'!$A$2:$A$392,0)),"row not found"))) | Q3: =IF(H3="Manual",IF(L3="","",L3),IF(N3="","",IFERROR(INDEX('Book rows'!$F$2:$F$392,MATCH(N3,'Book rows'!$A$2:$A$392,0)),"row not found")))
A4: Battle Hardened I | B4: Zocelený bojem I | C4: Features / Combat features | D4: 176 | E4: Zocelený bojem | F4: Name looks alike (0.93); check it is the same feature | G4: r307 Zocelený (0.67); r166 Zákeřný boj (0.59); r16 Expert boje (0.52); r508 Železná kůže (0.50) | N4: =IF(H4="Accept",D4,IF(H4="Use row",I4,"")) | O4: =IF(H4="Manual",IF(J4="","",J4),IF(N4="","",IFERROR(INDEX('Book rows'!$D$2:$D$392,MATCH(N4,'Book rows'!$A$2:$A$392,0)),"row not found"))) | P4: =IF(H4="Manual",IF(K4="","",K4),IF(N4="","",IFERROR(INDEX('Book rows'!$E$2:$E$392,MATCH(N4,'Book rows'!$A$2:$A$392,0)),"row not found"))) | Q4: =IF(H4="Manual",IF(L4="","",L4),IF(N4="","",IFERROR(INDEX('Book rows'!$F$2:$F$392,MATCH(N4,'Book rows'!$A$2:$A$392,0)),"row not found")))
A5: Combat Genius | B5: Bojový génius | C5: Features / Combat features | D5: 38 | E5: Bojový génius I | F5: Book has tiers (I, II...) but the pack has one item; tier I suggested | G5: r40 Bojový génius II (0.90); r187 Bojová připravenost (0.56); r629 Obojživelník (0.56); r267 Spolubojovník (0.54) | N5: =IF(H5="Accept",D5,IF(H5="Use row",I5,"")) | O5: =IF(H5="Manual",IF(J5="","",J5),IF(N5="","",IFERROR(INDEX('Book rows'!$D$2:$D$392,MATCH(N5,'Book rows'!$A$2:$A$392,0)),"row not found"))) | P5: =IF(H5="Manual",IF(K5="","",K5),IF(N5="","",IFERROR(INDEX('Book rows'!$E$2:$E$392,MATCH(N5,'Book rows'!$A$2:$A$392,0)),"row not found"))) | Q5: =IF(H5="Manual",IF(L5="","",L5),IF(N5="","",IFERROR(INDEX('Book rows'!$F$2:$F$392,MATCH(N5,'Book rows'!$A$2:$A$392,0)),"row not found")))
A6: Deadly Lunge | B6: Smrtící výpad | C6: Features / Combat features | D6: 140 | E6: Smrtící výpad I | F6: Book has tiers (I, II...) but the pack has one item; tier I suggested | G6: r142 Smrtící výpad II (0.90); r821 Smrtící spáry (0.77); r104 Precizní výpad (0.67); r659 Dračí výdrž (0.58) | N6: =IF(H6="Accept",D6,IF(H6="Use row",I6,"")) | O6: =IF(H6="Manual",IF(J6="","",J6),IF(N6="","",IFERROR(INDEX('Book rows'!$D$2:$D$392,MATCH(N6,'Book rows'!$A$2:$A$392,0)),"row not found"))) | P6: =IF(H6="Manual",IF(K6="","",K6),IF(N6="","",IFERROR(INDEX('Book rows'!$E$2:$E$392,MATCH(N6,'Book rows'!$A$2:$A$392,0)),"row not found"))) | Q6: =IF(H6="Manual",IF(L6="","",L6),IF(N6="","",IFERROR(INDEX('Book rows'!$F$2:$F$392,MATCH(N6,'Book rows'!$A$2:$A$392,0)),"row not found")))
A7: Deep Slash | B7: Hluboký sek | C7: Features / Combat features | D7: 702 | E7: Hluboký spánek | F7: Name looks alike (0.88); check it is the same feature | G7: r797 Hluboká znalost (0.62); r54 Hluboká rána (0.61); r324 Hluboké soustředění (0.60); r422 Hluboká nenávist (0.59) | N7: =IF(H7="Accept",D7,IF(H7="Use row",I7,"")) | O7: =IF(H7="Manual",IF(J7="","",J7),IF(N7="","",IFERROR(INDEX('Book rows'!$D$2:$D$392,MATCH(N7,'Book rows'!$A$2:$A$392,0)),"row not found"))) | P7: =IF(H7="Manual",IF(K7="","",K7),IF(N7="","",IFERROR(INDEX('Book rows'!$E$2:$E$392,MATCH(N7,'Book rows'!$A$2:$A$392,0)),"row not found"))) | Q7: =IF(H7="Manual",IF(L7="","",L7),IF(N7="","",IFERROR(INDEX('Book rows'!$F$2:$F$392,MATCH(N7,'Book rows'!$A$2:$A$392,0)),"row not found")))
A8: Endurance of Stone | B8: Kamenná výdrž | C8: Features / Combat features | F8: No real candidate in the book | G8: r659 Dračí výdrž (0.58); r360 Temperament Vody (0.48); r104 Precizní výpad (0.44); r373 Kouzelné zvíře (0.44); r376 Temperament Vzduchu (0.44) | N8: =IF(H8="Accept",D8,IF(H8="Use row",I8,"")) | O8: =IF(H8="Manual",IF(J8="","",J8),IF(N8="","",IFERROR(INDEX('Book rows'!$D$2:$D$392,MATCH(N8,'Book rows'!$A$2:$A$392,0)),"row not found"))) | P8: =IF(H8="Manual",IF(K8="","",K8),IF(N8="","",IFERROR(INDEX('Book rows'!$E$2:$E$392,MATCH(N8,'Book rows'!$A$2:$A$392,0)),"row not found"))) | Q8: =IF(H8="Manual",IF(L8="","",L8),IF(N8="","",IFERROR(INDEX('Book rows'!$F$2:$F$392,MATCH(N8,'Book rows'!$A$2:$A$392,0)),"row not found")))
A9: Flesh Rending | B9: Drásání | C9: Features / Combat features | F9: No real candidate in the book | G9: r795 Moudrá sova (0.56); r749 Prastarý (0.53); r663 Dračí šupiny (0.53); r559 Dar Calistei (0.53); r116 Přetažení (0.50) | N9: =IF(H9="Accept",D9,IF(H9="Use row",I9,"")) | O9: =IF(H9="Manual",IF(J9="","",J9),IF(N9="","",IFERROR(INDEX('Book rows'!$D$2:$D$392,MATCH(N9,'Book rows'!$A$2:$A$392,0)),"row not found"))) | P9: =IF(H9="Manual",IF(K9="","",K9),IF(N9="","",IFERROR(INDEX('Book rows'!$E$2:$E$392,MATCH(N9,'Book rows'!$A$2:$A$392,0)),"row not found"))) | Q9: =IF(H9="Manual",IF(L9="","",L9),IF(N9="","",IFERROR(INDEX('Book rows'!$F$2:$F$392,MATCH(N9,'Book rows'!$A$2:$A$392,0)),"row not found")))
A10: Haste | B10: Zrychlení | C10: Features / Combat features | D10: 350 | E10: Zrychlené čarování | F10: Weak name match (0.67); likely wrong | G10: r724 Rozptýlení (0.63); r128 Rychlý útočník (0.61); r813 Rychlý stín (0.60); r126 Rychlé ruce (0.60) | N10: =IF(H10="Accept",D10,IF(H10="Use row",I10,"")) | O10: =IF(H10="Manual",IF(J10="","",J10),IF(N10="","",IFERROR(INDEX('Book rows'!$D$2:$D$392,MATCH(N10,'Book rows'!$A$2:$A$392,0)),"row not found"))) | P10: =IF(H10="Manual",IF(K10="","",K10),IF(N10="","",IFERROR(INDEX('Book rows'!$E$2:$E$392,MATCH(N10,'Book rows'!$A$2:$A$392,0)),"row not found"))) | Q10: =IF(H10="Manual",IF(L10="","",L10),IF(N10="","",IFERROR(INDEX('Book rows'!$F$2:$F$392,MATCH(N10,'Book rows'!$A$2:$A$392,0)),"row not found")))
A11: Huntsman | B11: Lovec | C11: Features / Combat features | D11: 281 | E11: Svalovec I | F11: Weak name match (0.67); likely wrong | G11: r283 Svalovec II (0.62); r42 Dobrý lovec (0.62); r803 Rychlý lovec (0.59); r811 Zlodějíček (0.53) | N11: =IF(H11="Accept",D11,IF(H11="Use row",I11,"")) | O11: =IF(H11="Manual",IF(J11="","",J11),IF(N11="","",IFERROR(INDEX('Book rows'!$D$2:$D$392,MATCH(N11,'Book rows'!$A$2:$A$392,0)),"row not found"))) | P11: =IF(H11="Manual",IF(K11="","",K11),IF(N11="","",IFERROR(INDEX('Book rows'!$E$2:$E$392,MATCH(N11,'Book rows'!$A$2:$A$392,0)),"row not found"))) | Q11: =IF(H11="Manual",IF(L11="","",L11),IF(N11="","",IFERROR(INDEX('Book rows'!$F$2:$F$392,MATCH(N11,'Book rows'!$A$2:$A$392,0)),"row not found")))
A12: Leg Sweep | B12: Podkopnutí | C12: Features / Combat features | D12: 355 | E12: Podpálení | F12: Weak name match (0.63); likely wrong | G12: r106 Prohození (0.53); r743 Divoké rozseknutí (0.52); r458 Dotek pochopení (0.48); r70 Krvavé nabodnutí (0.46) | N12: =IF(H12="Accept",D12,IF(H12="Use row",I12,"")) | O12: =IF(H12="Manual",IF(J12="","",J12),IF(N12="","",IFERROR(INDEX('Book rows'!$D$2:$D$392,MATCH(N12,'Book rows'!$A$2:$A$392,0)),"row not found"))) | P12: =IF(H12="Manual",IF(K12="","",K12),IF(N12="","",IFERROR(INDEX('Book rows'!$E$2:$E$392,MATCH(N12,'Book rows'!$A$2:$A$392,0)),"row not found"))) | Q12: =IF(H12="Manual",IF(L12="","",L12),IF(N12="","",IFERROR(INDEX('Book rows'!$F$2:$F$392,MATCH(N12,'Book rows'!$A$2:$A$392,0)),"row not found")))
A13: Perseverance | B13: Vytrvalost | C13: Features / Combat features | D13: 637 | E13: Ještěří vytrvalost | F13: Weak name match (0.71); likely wrong | G13: r737 Yormunská vytrvalost (0.67); r496 Trpasličí vytrvalost (0.67); r30 Atletická vytrvalost (0.67); r676 Netrpělivost (0.55) | N13: =IF(H13="Accept",D13,IF(H13="Use row",I13,"")) | O13: =IF(H13="Manual",IF(J13="","",J13),IF(N13="","",IFERROR(INDEX('Book rows'!$D$2:$D$392,MATCH(N13,'Book rows'!$A$2:$A$392,0)),"row not found"))) | P13: =IF(H13="Manual",IF(K13="","",K13),IF(N13="","",IFERROR(INDEX('Book rows'!$E$2:$E$392,MATCH(N13,'Book rows'!$A$2:$A$392,0)),"row not found"))) | Q13: =IF(H13="Manual",IF(L13="","",L13),IF(N13="","",IFERROR(INDEX('Book rows'!$F$2:$F$392,MATCH(N13,'Book rows'!$A$2:$A$392,0)),"row not found")))
A14: Polearm master | B14: Mistr ratišťových zbraní | C14: Features / Combat features | F14: No real candidate in the book | G14: r243 Mistr slov (0.53); r241 Mistr pastí (0.51); r46 Exotické zbraně I (0.49); r48 Exotické zbraně II (0.48); r76 Mistr vrhu (0.47) | N14: =IF(H14="Accept",D14,IF(H14="Use row",I14,"")) | O14: =IF(H14="Manual",IF(J14="","",J14),IF(N14="","",IFERROR(INDEX('Book rows'!$D$2:$D$392,MATCH(N14,'Book rows'!$A$2:$A$392,0)),"row not found"))) | P14: =IF(H14="Manual",IF(K14="","",K14),IF(N14="","",IFERROR(INDEX('Book rows'!$E$2:$E$392,MATCH(N14,'Book rows'!$A$2:$A$392,0)),"row not found"))) | Q14: =IF(H14="Manual",IF(L14="","",L14),IF(N14="","",IFERROR(INDEX('Book rows'!$F$2:$F$392,MATCH(N14,'Book rows'!$A$2:$A$392,0)),"row not found")))
A15: Precise lunge | B15: Přesný výpad | C15: Features / Combat features | D15: 104 | E15: Precizní výpad | F15: Weak name match (0.77); likely wrong | G15: r114 Přesný zásah (0.67); r716 Přirozený vůdce (0.59); r809 Černý pařát (0.52); r140 Smrtící výpad I (0.52) | N15: =IF(H15="Accept",D15,IF(H15="Use row",I15,"")) | O15: =IF(H15="Manual",IF(J15="","",J15),IF(N15="","",IFERROR(INDEX('Book rows'!$D$2:$D$392,MATCH(N15,'Book rows'!$A$2:$A$392,0)),"row not found"))) | P15: =IF(H15="Manual",IF(K15="","",K15),IF(N15="","",IFERROR(INDEX('Book rows'!$E$2:$E$392,MATCH(N15,'Book rows'!$A$2:$A$392,0)),"row not found"))) | Q15: =IF(H15="Manual",IF(L15="","",L15),IF(N15="","",IFERROR(INDEX('Book rows'!$F$2:$F$392,MATCH(N15,'Book rows'!$A$2:$A$392,0)),"row not found")))
A16: Precision strike | B16: Přesný úder | C16: Features / Combat features | D16: 716 | E16: Přirozený vůdce | F16: Weak name match (0.69); likely wrong | G16: r114 Přesný zásah (0.61); r561 Mořský dech (0.55); r762 Požehnaný dotek (0.54); r694 Bezedný žaludek (0.54) | N16: =IF(H16="Accept",D16,IF(H16="Use row",I16,"")) | O16: =IF(H16="Manual",IF(J16="","",J16),IF(N16="","",IFERROR(INDEX('Book rows'!$D$2:$D$392,MATCH(N16,'Book rows'!$A$2:$A$392,0)),"row not found"))) | P16: =IF(H16="Manual",IF(K16="","",K16),IF(N16="","",IFERROR(INDEX('Book rows'!$E$2:$E$392,MATCH(N16,'Book rows'!$A$2:$A$392,0)),"row not found"))) | Q16: =IF(H16="Manual",IF(L16="","",L16),IF(N16="","",IFERROR(INDEX('Book rows'!$F$2:$F$392,MATCH(N16,'Book rows'!$A$2:$A$392,0)),"row not found")))
A17: Speedy advantage | B17: Výhoda rychlosti | C17: Features / Combat features | F17: No real candidate in the book | G17: r813 Rychlý stín (0.59); r559 Dar Calistei (0.57); r797 Hluboká znalost (0.52); r471 Lidská učenlivost I (0.51); r714 Vražedná zarputilost (0.50) | N17: =IF(H17="Accept",D17,IF(H17="Use row",I17,"")) | O17: =IF(H17="Manual",IF(J17="","",J17),IF(N17="","",IFERROR(INDEX('Book rows'!$D$2:$D$392,MATCH(N17,'Book rows'!$A$2:$A$392,0)),"row not found"))) | P17: =IF(H17="Manual",IF(K17="","",K17),IF(N17="","",IFERROR(INDEX('Book rows'!$E$2:$E$392,MATCH(N17,'Book rows'!$A$2:$A$392,0)),"row not found"))) | Q17: =IF(H17="Manual",IF(L17="","",L17),IF(N17="","",IFERROR(INDEX('Book rows'!$F$2:$F$392,MATCH(N17,'Book rows'!$A$2:$A$392,0)),"row not found")))
A18: Strain | B18: Vypětí | C18: Features / Combat features | F18: No real candidate in the book | G18: r116 Přetažení (0.53); r213 Expertíza (0.53); r100 Práče I (0.46); r102 Práče II (0.43); r512 Partizán (0.43) | N18: =IF(H18="Accept",D18,IF(H18="Use row",I18,"")) | O18: =IF(H18="Manual",IF(J18="","",J18),IF(N18="","",IFERROR(INDEX('Book rows'!$D$2:$D$392,MATCH(N18,'Book rows'!$A$2:$A$392,0)),"row not found"))) | P18: =IF(H18="Manual",IF(K18="","",K18),IF(N18="","",IFERROR(INDEX('Book rows'!$E$2:$E$392,MATCH(N18,'Book rows'!$A$2:$A$392,0)),"row not found"))) | Q18: =IF(H18="Manual",IF(L18="","",L18),IF(N18="","",IFERROR(INDEX('Book rows'!$F$2:$F$392,MATCH(N18,'Book rows'!$A$2:$A$392,0)),"row not found")))
A19: Sundering Blows I | B19: Drtivé údery I | C19: Features / Combat features | D19: 665 | E19: Dračí dech I | F19: Weak name match (0.62); likely wrong | G19: r667 Dračí dech II (0.59); r678 Zuřivé plameny (0.50); r551 Dar Caerys (0.50); r140 Smrtící výpad I (0.48) | N19: =IF(H19="Accept",D19,IF(H19="Use row",I19,"")) | O19: =IF(H19="Manual",IF(J19="","",J19),IF(N19="","",IFERROR(INDEX('Book rows'!$D$2:$D$392,MATCH(N19,'Book rows'!$A$2:$A$392,0)),"row not found"))) | P19: =IF(H19="Manual",IF(K19="","",K19),IF(N19="","",IFERROR(INDEX('Book rows'!$E$2:$E$392,MATCH(N19,'Book rows'!$A$2:$A$392,0)),"row not found"))) | Q19: =IF(H19="Manual",IF(L19="","",L19),IF(N19="","",IFERROR(INDEX('Book rows'!$F$2:$F$392,MATCH(N19,'Book rows'!$A$2:$A$392,0)),"row not found")))
A20: Sundering Blows II | B20: Drtivé údery II | C20: Features / Combat features | D20: 667 | E20: Dračí dech II | F20: Weak name match (0.64); likely wrong | G20: r665 Dračí dech I (0.59); r142 Smrtící výpad II (0.52); r110 Průbojné rány II (0.52); r48 Exotické zbraně II (0.48) | N20: =IF(H20="Accept",D20,IF(H20="Use row",I20,"")) | O20: =IF(H20="Manual",IF(J20="","",J20),IF(N20="","",IFERROR(INDEX('Book rows'!$D$2:$D$392,MATCH(N20,'Book rows'!$A$2:$A$392,0)),"row not found"))) | P20: =IF(H20="Manual",IF(K20="","",K20),IF(N20="","",IFERROR(INDEX('Book rows'!$E$2:$E$392,MATCH(N20,'Book rows'!$A$2:$A$392,0)),"row not found"))) | Q20: =IF(H20="Manual",IF(L20="","",L20),IF(N20="","",IFERROR(INDEX('Book rows'!$F$2:$F$392,MATCH(N20,'Book rows'!$A$2:$A$392,0)),"row not found")))
A21: Dwarven toughness | B21: Trpasličí houževnatost | C21: Features / Dwarven features | D21: 500 | E21: Trpasličí odolnost | F21: Weak name match (0.75); likely wrong | G21: r496 Trpasličí vytrvalost (0.71); r498 Trpasličí nezdolnost (0.71); r56 Houževnatost (0.71); r506 Trpasličí talent (0.68) | N21: =IF(H21="Accept",D21,IF(H21="Use row",I21,"")) | O21: =IF(H21="Manual",IF(J21="","",J21),IF(N21="","",IFERROR(INDEX('Book rows'!$D$2:$D$392,MATCH(N21,'Book rows'!$A$2:$A$392,0)),"row not found"))) | P21: =IF(H21="Manual",IF(K21="","",K21),IF(N21="","",IFERROR(INDEX('Book rows'!$E$2:$E$392,MATCH(N21,'Book rows'!$A$2:$A$392,0)),"row not found"))) | Q21: =IF(H21="Manual",IF(L21="","",L21),IF(N21="","",IFERROR(INDEX('Book rows'!$F$2:$F$392,MATCH(N21,'Book rows'!$A$2:$A$392,0)),"row not found")))
A22: Elven grace | B22: Elfí ladnost | C22: Features / Elven features | D22: 541 | E22: Měsíční ladnost | F22: Weak name match (0.74); likely wrong | G22: r519 Elfská zručnost (0.59); r521 Elfská mrštnost (0.59); r531 Elfský talent (0.56); r533 Elfská dokonalost (0.55) | N22: =IF(H22="Accept",D22,IF(H22="Use row",I22,"")) | O22: =IF(H22="Manual",IF(J22="","",J22),IF(N22="","",IFERROR(INDEX('Book rows'!$D$2:$D$392,MATCH(N22,'Book rows'!$A$2:$A$392,0)),"row not found"))) | P22: =IF(H22="Manual",IF(K22="","",K22),IF(N22="","",IFERROR(INDEX('Book rows'!$E$2:$E$392,MATCH(N22,'Book rows'!$A$2:$A$392,0)),"row not found"))) | Q22: =IF(H22="Manual",IF(L22="","",L22),IF(N22="","",IFERROR(INDEX('Book rows'!$F$2:$F$392,MATCH(N22,'Book rows'!$A$2:$A$392,0)),"row not found")))
A23: Elven reflexes | B23: Elfí reflexy | C23: Features / Elven features | D23: 523 | E23: Elfské reflexy | F23: Name looks alike (0.85); check it is the same feature | G23: r779 Dravčí reflexy (0.69); r36 Bleskové reflexy (0.64); r531 Elfský talent (0.48); r442 Přítel lesa (0.43) | N23: =IF(H23="Accept",D23,IF(H23="Use row",I23,"")) | O23: =IF(H23="Manual",IF(J23="","",J23),IF(N23="","",IFERROR(INDEX('Book rows'!$D$2:$D$392,MATCH(N23,'Book rows'!$A$2:$A$392,0)),"row not found"))) | P23: =IF(H23="Manual",IF(K23="","",K23),IF(N23="","",IFERROR(INDEX('Book rows'!$E$2:$E$392,MATCH(N23,'Book rows'!$A$2:$A$392,0)),"row not found"))) | Q23: =IF(H23="Manual",IF(L23="","",L23),IF(N23="","",IFERROR(INDEX('Book rows'!$F$2:$F$392,MATCH(N23,'Book rows'!$A$2:$A$392,0)),"row not found")))
A24: Studiousness | B24: Učenost | C24: Features / Elven features | D24: 295 | E24: Umíněnost | F24: Weak name match (0.75); likely wrong | G24: r56 Houževnatost (0.63); r608 Pulčická zákeřnost (0.56); r430 Náměsíčnost (0.56); r519 Elfská zručnost (0.55) | N24: =IF(H24="Accept",D24,IF(H24="Use row",I24,"")) | O24: =IF(H24="Manual",IF(J24="","",J24),IF(N24="","",IFERROR(INDEX('Book rows'!$D$2:$D$392,MATCH(N24,'Book rows'!$A$2:$A$392,0)),"row not found"))) | P24: =IF(H24="Manual",IF(K24="","",K24),IF(N24="","",IFERROR(INDEX('Book rows'!$E$2:$E$392,MATCH(N24,'Book rows'!$A$2:$A$392,0)),"row not found"))) | Q24: =IF(H24="Manual",IF(L24="","",L24),IF(N24="","",IFERROR(INDEX('Book rows'!$F$2:$F$392,MATCH(N24,'Book rows'!$A$2:$A$392,0)),"row not found")))
A25: Elven perfection: Acrobacy | B25: Elfí dokonalost: Akrobacie | C25: Features / Elven features / Elven perfection | D25: 533 | E25: Elfská dokonalost | F25: Family rule: Elven perfection (book prices every skill alike) | G25: r710 Ješitná dokonalost (0.60); r322 Doteková stabilizace (0.53); r785 Znalost dynastie (0.49); r80 Nezdolnost kamene (0.48) | H25: Accept | N25: =IF(H25="Accept",D25,IF(H25="Use row",I25,"")) | O25: =IF(H25="Manual",IF(J25="","",J25),IF(N25="","",IFERROR(INDEX('Book rows'!$D$2:$D$392,MATCH(N25,'Book rows'!$A$2:$A$392,0)),"row not found"))) | P25: =IF(H25="Manual",IF(K25="","",K25),IF(N25="","",IFERROR(INDEX('Book rows'!$E$2:$E$392,MATCH(N25,'Book rows'!$A$2:$A$392,0)),"row not found"))) | Q25: =IF(H25="Manual",IF(L25="","",L25),IF(N25="","",IFERROR(INDEX('Book rows'!$F$2:$F$392,MATCH(N25,'Book rows'!$A$2:$A$392,0)),"row not found")))
A26: Elven perfection: Alchemy | B26: Elfí dokonalost: Alchymie | C26: Features / Elven features / Elven perfection | D26: 533 | E26: Elfská dokonalost | F26: Family rule: Elven perfection (book prices every skill alike) | G26: r710 Ješitná dokonalost (0.62); r80 Nezdolnost kamene (0.54); r263 Rozbor alchemie (0.51); r785 Znalost dynastie (0.50) | H26: Accept | N26: =IF(H26="Accept",D26,IF(H26="Use row",I26,"")) | O26: =IF(H26="Manual",IF(J26="","",J26),IF(N26="","",IFERROR(INDEX('Book rows'!$D$2:$D$392,MATCH(N26,'Book rows'!$A$2:$A$392,0)),"row not found"))) | P26: =IF(H26="Manual",IF(K26="","",K26),IF(N26="","",IFERROR(INDEX('Book rows'!$E$2:$E$392,MATCH(N26,'Book rows'!$A$2:$A$392,0)),"row not found"))) | Q26: =IF(H26="Manual",IF(L26="","",L26),IF(N26="","",IFERROR(INDEX('Book rows'!$F$2:$F$392,MATCH(N26,'Book rows'!$A$2:$A$392,0)),"row not found")))
A27: Elven perfection: Arcana | B27: Elfí dokonalost: Arcana | C27: Features / Elven features / Elven perfection | D27: 533 | E27: Elfská dokonalost | F27: Family rule: Elven perfection (book prices every skill alike) | G27: r710 Ješitná dokonalost (0.65); r54 Hluboká rána (0.53); r80 Nezdolnost kamene (0.51); r557 Klidná hladina (0.50) | H27: Accept | N27: =IF(H27="Accept",D27,IF(H27="Use row",I27,"")) | O27: =IF(H27="Manual",IF(J27="","",J27),IF(N27="","",IFERROR(INDEX('Book rows'!$D$2:$D$392,MATCH(N27,'Book rows'!$A$2:$A$392,0)),"row not found"))) | P27: =IF(H27="Manual",IF(K27="","",K27),IF(N27="","",IFERROR(INDEX('Book rows'!$E$2:$E$392,MATCH(N27,'Book rows'!$A$2:$A$392,0)),"row not found"))) | Q27: =IF(H27="Manual",IF(L27="","",L27),IF(N27="","",IFERROR(INDEX('Book rows'!$F$2:$F$392,MATCH(N27,'Book rows'!$A$2:$A$392,0)),"row not found")))
A28: Elven perfection: Athletics | B28: Elfí dokonalost: Atletika | C28: Features / Elven features / Elven perfection | D28: 533 | E28: Elfská dokonalost | F28: Family rule: Elven perfection (book prices every skill alike) | G28: r710 Ješitná dokonalost (0.62); r785 Znalost dynastie (0.50); r80 Nezdolnost kamene (0.49); r623 Odolnost na jedy I (0.48) | H28: Accept | N28: =IF(H28="Accept",D28,IF(H28="Use row",I28,"")) | O28: =IF(H28="Manual",IF(J28="","",J28),IF(N28="","",IFERROR(INDEX('Book rows'!$D$2:$D$392,MATCH(N28,'Book rows'!$A$2:$A$392,0)),"row not found"))) | P28: =IF(H28="Manual",IF(K28="","",K28),IF(N28="","",IFERROR(INDEX('Book rows'!$E$2:$E$392,MATCH(N28,'Book rows'!$A$2:$A$392,0)),"row not found"))) | Q28: =IF(H28="Manual",IF(L28="","",L28),IF(N28="","",IFERROR(INDEX('Book rows'!$F$2:$F$392,MATCH(N28,'Book rows'!$A$2:$A$392,0)),"row not found")))
A29: Elven perfection: First Aid | B29: Elfí dokonalost: Ranhojičství | C29: Features / Elven features / Elven perfection | D29: 533 | E29: Elfská dokonalost | F29: Family rule: Elven perfection (book prices every skill alike) | G29: r710 Ješitná dokonalost (0.57); r785 Znalost dynastie (0.50); r197 *Dovednost A*: Mistr (0.49); r639 Odolnost na jedy II (0.47) | H29: Accept | N29: =IF(H29="Accept",D29,IF(H29="Use row",I29,"")) | O29: =IF(H29="Manual",IF(J29="","",J29),IF(N29="","",IFERROR(INDEX('Book rows'!$D$2:$D$392,MATCH(N29,'Book rows'!$A$2:$A$392,0)),"row not found"))) | P29: =IF(H29="Manual",IF(K29="","",K29),IF(N29="","",IFERROR(INDEX('Book rows'!$E$2:$E$392,MATCH(N29,'Book rows'!$A$2:$A$392,0)),"row not found"))) | Q29: =IF(H29="Manual",IF(L29="","",L29),IF(N29="","",IFERROR(INDEX('Book rows'!$F$2:$F$392,MATCH(N29,'Book rows'!$A$2:$A$392,0)),"row not found")))
A30: Elven perfection: Leadership | B30: Elfí dokonalost: Velení | C30: Features / Elven features / Elven perfection | D30: 533 | E30: Elfská dokonalost | F30: Family rule: Elven perfection (book prices every skill alike) | G30: r710 Ješitná dokonalost (0.65); r80 Nezdolnost kamene (0.51); r324 Hluboké soustředění (0.49); r797 Hluboká znalost (0.49) | H30: Accept | N30: =IF(H30="Accept",D30,IF(H30="Use row",I30,"")) | O30: =IF(H30="Manual",IF(J30="","",J30),IF(N30="","",IFERROR(INDEX('Book rows'!$D$2:$D$392,MATCH(N30,'Book rows'!$A$2:$A$392,0)),"row not found"))) | P30: =IF(H30="Manual",IF(K30="","",K30),IF(N30="","",IFERROR(INDEX('Book rows'!$E$2:$E$392,MATCH(N30,'Book rows'!$A$2:$A$392,0)),"row not found"))) | Q30: =IF(H30="Manual",IF(L30="","",L30),IF(N30="","",IFERROR(INDEX('Book rows'!$F$2:$F$392,MATCH(N30,'Book rows'!$A$2:$A$392,0)),"row not found")))
A31: Elven perfection: Pickpocketing | B31: Elfí dokonalost: Kapsářství | C31: Features / Elven features / Elven perfection | D31: 533 | E31: Elfská dokonalost | F31: Family rule: Elven perfection (book prices every skill alike) | G31: r710 Ješitná dokonalost (0.59); r785 Znalost dynastie (0.52); r195 *Dovednost A*: Expert (0.50); r80 Nezdolnost kamene (0.47) | H31: Accept | N31: =IF(H31="Accept",D31,IF(H31="Use row",I31,"")) | O31: =IF(H31="Manual",IF(J31="","",J31),IF(N31="","",IFERROR(INDEX('Book rows'!$D$2:$D$392,MATCH(N31,'Book rows'!$A$2:$A$392,0)),"row not found"))) | P31: =IF(H31="Manual",IF(K31="","",K31),IF(N31="","",IFERROR(INDEX('Book rows'!$E$2:$E$392,MATCH(N31,'Book rows'!$A$2:$A$392,0)),"row not found"))) | Q31: =IF(H31="Manual",IF(L31="","",L31),IF(N31="","",IFERROR(INDEX('Book rows'!$F$2:$F$392,MATCH(N31,'Book rows'!$A$2:$A$392,0)),"row not found")))
A32: Elven perfection: Stealth | B32: Elfí dokonalost: Plížení | C32: Features / Elven features / Elven perfection | D32: 533 | E32: Elfská dokonalost | F32: Family rule: Elven perfection (book prices every skill alike) | G32: r710 Ješitná dokonalost (0.63); r322 Doteková stabilizace (0.51); r80 Nezdolnost kamene (0.50); r797 Hluboká znalost (0.47) | H32: Accept | N32: =IF(H32="Accept",D32,IF(H32="Use row",I32,"")) | O32: =IF(H32="Manual",IF(J32="","",J32),IF(N32="","",IFERROR(INDEX('Book rows'!$D$2:$D$392,MATCH(N32,'Book rows'!$A$2:$A$392,0)),"row not found"))) | P32: =IF(H32="Manual",IF(K32="","",K32),IF(N32="","",IFERROR(INDEX('Book rows'!$E$2:$E$392,MATCH(N32,'Book rows'!$A$2:$A$392,0)),"row not found"))) | Q32: =IF(H32="Manual",IF(L32="","",L32),IF(N32="","",IFERROR(INDEX('Book rows'!$F$2:$F$392,MATCH(N32,'Book rows'!$A$2:$A$392,0)),"row not found")))
A33: Elven talent: Animal Handling | B33: Elfí talent: Zacházení se zvířaty | C33: Features / Elven features / Elven talent: *Skill* | D33: 531 | E33: Elfský talent | F33: Family rule: Elven talent (book prices every skill alike) | G33: r438 Spojení se zvířaty (0.56); r275 Společník zvířat (0.50); r146 Specializace na zbraň I (0.44); r148 Specializace na zbraň II (0.43) | H33: Accept | N33: =IF(H33="Accept",D33,IF(H33="Use row",I33,"")) | O33: =IF(H33="Manual",IF(J33="","",J33),IF(N33="","",IFERROR(INDEX('Book rows'!$D$2:$D$392,MATCH(N33,'Book rows'!$A$2:$A$392,0)),"row not found"))) | P33: =IF(H33="Manual",IF(K33="","",K33),IF(N33="","",IFERROR(INDEX('Book rows'!$E$2:$E$392,MATCH(N33,'Book rows'!$A$2:$A$392,0)),"row not found"))) | Q33: =IF(H33="Manual",IF(L33="","",L33),IF(N33="","",IFERROR(INDEX('Book rows'!$F$2:$F$392,MATCH(N33,'Book rows'!$A$2:$A$392,0)),"row not found")))
A34: Elven talent: Arcana | B34: Elfí talent: Arcana | C34: Features / Elven features / Elven talent: *Skill* | D34: 531 | E34: Elfský talent | F34: Family rule: Elven talent (book prices every skill alike) | G34: r112 Brutální rána (0.58); r506 Trpasličí talent (0.53); r479 Talentovaný I (0.52); r481 Talentovaný II (0.50) | H34: Accept | N34: =IF(H34="Accept",D34,IF(H34="Use row",I34,"")) | O34: =IF(H34="Manual",IF(J34="","",J34),IF(N34="","",IFERROR(INDEX('Book rows'!$D$2:$D$392,MATCH(N34,'Book rows'!$A$2:$A$392,0)),"row not found"))) | P34: =IF(H34="Manual",IF(K34="","",K34),IF(N34="","",IFERROR(INDEX('Book rows'!$E$2:$E$392,MATCH(N34,'Book rows'!$A$2:$A$392,0)),"row not found"))) | Q34: =IF(H34="Manual",IF(L34="","",L34),IF(N34="","",IFERROR(INDEX('Book rows'!$F$2:$F$392,MATCH(N34,'Book rows'!$A$2:$A$392,0)),"row not found")))
A35: Elven talent: Athletics | B35: Elfí talent: Atletika | C35: Features / Elven features / Elven talent: *Skill* | D35: 531 | E35: Elfský talent | F35: Family rule: Elven talent (book prices every skill alike) | G35: r506 Trpasličí talent (0.50); r479 Talentovaný I (0.48); r481 Talentovaný II (0.47); r527 Elfská učenlivost I (0.46) | H35: Accept | N35: =IF(H35="Accept",D35,IF(H35="Use row",I35,"")) | O35: =IF(H35="Manual",IF(J35="","",J35),IF(N35="","",IFERROR(INDEX('Book rows'!$D$2:$D$392,MATCH(N35,'Book rows'!$A$2:$A$392,0)),"row not found"))) | P35: =IF(H35="Manual",IF(K35="","",K35),IF(N35="","",IFERROR(INDEX('Book rows'!$E$2:$E$392,MATCH(N35,'Book rows'!$A$2:$A$392,0)),"row not found"))) | Q35: =IF(H35="Manual",IF(L35="","",L35),IF(N35="","",IFERROR(INDEX('Book rows'!$F$2:$F$392,MATCH(N35,'Book rows'!$A$2:$A$392,0)),"row not found")))
A36: Elven talent: First Aid | B36: Elfí talent: Ranhojičství | C36: Features / Elven features / Elven talent: *Skill* | D36: 531 | E36: Elfský talent | F36: Family rule: Elven talent (book prices every skill alike) | G36: r481 Talentovaný II (0.53); r483 Talentovaný III (0.51); r148 Specializace na zbraň II (0.50); r479 Talentovaný I (0.49) | H36: Accept | N36: =IF(H36="Accept",D36,IF(H36="Use row",I36,"")) | O36: =IF(H36="Manual",IF(J36="","",J36),IF(N36="","",IFERROR(INDEX('Book rows'!$D$2:$D$392,MATCH(N36,'Book rows'!$A$2:$A$392,0)),"row not found"))) | P36: =IF(H36="Manual",IF(K36="","",K36),IF(N36="","",IFERROR(INDEX('Book rows'!$E$2:$E$392,MATCH(N36,'Book rows'!$A$2:$A$392,0)),"row not found"))) | Q36: =IF(H36="Manual",IF(L36="","",L36),IF(N36="","",IFERROR(INDEX('Book rows'!$F$2:$F$392,MATCH(N36,'Book rows'!$A$2:$A$392,0)),"row not found")))
... A55: Specialization: Traps | B55: Specializace: Pasti | C55: Features / Elven features / Specialization: *Skill* | D55: 525 | E55: Specializace: *Dovednost* | F55: Family rule: Elven specialization (book prices every skill alike) | G55: r469 Specializace: *Dovednost* (0.75); r752 Specializace: *Dovednost* (0.75); r146 Specializace na zbraň I (0.73); r148 Specializace na zbraň II (0.71); r487 Specialista (0.69) | H55: Accept | N55: =IF(H55="Accept",D55,IF(H55="Use row",I55,"")) | O55: =IF(H55="Manual",IF(J55="","",J55),IF(N55="","",IFERROR(INDEX('Book rows'!$D$2:$D$392,MATCH(N55,'Book rows'!$A$2:$A$392,0)),"row not found"))) | P55: =IF(H55="Manual",IF(K55="","",K55),IF(N55="","",IFERROR(INDEX('Book rows'!$E$2:$E$392,MATCH(N55,'Book rows'!$A$2:$A$392,0)),"row not found"))) | Q55: =IF(H55="Manual",IF(L55="","",L55),IF(N55="","",IFERROR(INDEX('Book rows'!$F$2:$F$392,MATCH(N55,'Book rows'!$A$2:$A$392,0)),"row not found")))
A56: Feather footed | B56: Lehkonohý | C56: Features / Halfling features | F56: No real candidate in the book | G56: r406 Hbité nohy (0.53); r307 Zocelený (0.47); r479 Talentovaný I (0.45); r829 Vůle bohů (0.44); r412 Nebojácný (0.44) | N56: =IF(H56="Accept",D56,IF(H56="Use row",I56,"")) | O56: =IF(H56="Manual",IF(J56="","",J56),IF(N56="","",IFERROR(INDEX('Book rows'!$D$2:$D$392,MATCH(N56,'Book rows'!$A$2:$A$392,0)),"row not found"))) | P56: =IF(H56="Manual",IF(K56="","",K56),IF(N56="","",IFERROR(INDEX('Book rows'!$E$2:$E$392,MATCH(N56,'Book rows'!$A$2:$A$392,0)),"row not found"))) | Q56: =IF(H56="Manual",IF(L56="","",L56),IF(N56="","",IFERROR(INDEX('Book rows'!$F$2:$F$392,MATCH(N56,'Book rows'!$A$2:$A$392,0)),"row not found")))
A57: Foodie | B57: Labužník | C57: Features / Halfling features | F57: No real candidate in the book | G57: r134 Řezník (0.57); r267 Spolubojovník (0.48); r170 Zbojník I (0.47); r116 Přetažení (0.47); r128 Rychlý útočník (0.45) | N57: =IF(H57="Accept",D57,IF(H57="Use row",I57,"")) | O57: =IF(H57="Manual",IF(J57="","",J57),IF(N57="","",IFERROR(INDEX('Book rows'!$D$2:$D$392,MATCH(N57,'Book rows'!$A$2:$A$392,0)),"row not found"))) | P57: =IF(H57="Manual",IF(K57="","",K57),IF(N57="","",IFERROR(INDEX('Book rows'!$E$2:$E$392,MATCH(N57,'Book rows'!$A$2:$A$392,0)),"row not found"))) | Q57: =IF(H57="Manual",IF(L57="","",L57),IF(N57="","",IFERROR(INDEX('Book rows'!$F$2:$F$392,MATCH(N57,'Book rows'!$A$2:$A$392,0)),"row not found")))
A58: Halfling insidiousness | B58: Půlčičí zákeřnost | C58: Features / Halfling features | D58: 608 | E58: Pulčická zákeřnost | F58: Name looks alike (0.91); check it is the same feature | G58: r645 Hadí zákeřnost (0.71); r606 Pulčické štěstí (0.62); r506 Trpasličí talent (0.61); r498 Trpasličí nezdolnost (0.59) | N58: =IF(H58="Accept",D58,IF(H58="Use row",I58,"")) | O58: =IF(H58="Manual",IF(J58="","",J58),IF(N58="","",IFERROR(INDEX('Book rows'!$D$2:$D$392,MATCH(N58,'Book rows'!$A$2:$A$392,0)),"row not found"))) | P58: =IF(H58="Manual",IF(K58="","",K58),IF(N58="","",IFERROR(INDEX('Book rows'!$E$2:$E$392,MATCH(N58,'Book rows'!$A$2:$A$392,0)),"row not found"))) | Q58: =IF(H58="Manual",IF(L58="","",L58),IF(N58="","",IFERROR(INDEX('Book rows'!$F$2:$F$392,MATCH(N58,'Book rows'!$A$2:$A$392,0)),"row not found")))
...

Sheet Auto-accepted
A1: Pack feature (English) | B1: Czech name | C1: Pack folder | D1: How matched | E1: Book row # | F1: Book name | G1: Cost | H1: Currency | I1: Requirements
A2: Armor Training I | B2: Výcvik se zbrojí I | C2: Features / Combat features | D2: Exact Czech name | E2: 162 | F2: Výcvik se zbrojí I | G2: 5 | H2: CP | I2: Odolnost 3; Učitel I
A3: Armor Training II | B3: Výcvik se zbrojí II | C3: Features / Combat features | D3: Exact Czech name | E3: 164 | F3: Výcvik se zbrojí II | G3: 10 | H3: CP | I3: Učitel I
A4: Cleaver Cleave | B4: Rozseknutí sekáčkem | C4: Features / Combat features | D4: Exact Czech name | E4: 132 | F4: Rozseknutí sekáčkem | G4: 10 | H4: CP | I4: Meče V
A5: Combat Genius II | B5: Bojový génius II | C5: Features / Combat features | D5: Exact Czech name | E5: 40 | F5: Bojový génius II | G5: 10 | H5: CP | I5: Bojový génius I; Doktrína VI; Inteligence 5
A6: Finesse | B6: Finesa | C6: Features / Combat features | D6: Exact Czech name | E6: 50 | F6: Finesa | G6: 10 | H6: CP | I6: Obratnost 3; Učitel I; Obratnost > Síla
A7: Flamberge Cleave | B7: Rozseknutí flambergem | C7: Features / Combat features | D7: Exact Czech name | E7: 130 | F7: Rozseknutí flambergem | G7: 5 | H7: CP | I7: Šermíř IV
A8: Free hand I | B8: Volná ruka I | C8: Features / Combat features | D8: Exact Czech name | E8: 158 | F8: Volná ruka I | G8: 10 | H8: CP | I8: Duelista III
A9: Free hand II | B9: Volná ruka II | C9: Features / Combat features | D9: Exact Czech name | E9: 160 | F9: Volná ruka II | G9: 10 | H9: CP | I9: Volná Ruka I; Duelista V
A10: Fuscina Ictus | B10: Fuscina Ictus | C10: Features / Combat features | D10: Exact Czech name | E10: 52 | F10: Fuscina Ictus | G10: 5 | H10: CP | I10: Dřevcové V
A11: Imbroccata | B11: Imbroccata | C11: Features / Combat features | D11: Exact Czech name | E11: 58 | F11: Imbroccata | G11: 5 | H11: CP | I11: Meče III
A12: Indestructible | B12: Nezničitelný | C12: Features / Combat features | D12: Exact Czech name | E12: 82 | F12: Nezničitelný | G12: 20 | H12: CP | I12: Tuhý kořínek / Odolnost 6
A13: Iron Muscles | B13: Železné svaly | C13: Features / Combat features | D13: Exact Czech name | E13: 178 | F13: Železné svaly | G13: 5 | H13: CP | I13: Síla > Odolnost
... A100: Expert: Traps | B100: Expert: Pasti | C100: Features / Experts | D100: Skill tier: traps is class C | E100: 207 | F100: *Dovednost C*: Expert | G100: 10 | H100: SP | I100: *Dovednost* VI; *Dovednost* Adept

Sheet Book rows
A1: Book row # | B1: Section | C1: Name (Czech) | D1: Cost | E1: Currency | F1: Requirements (Czech) | G1: Description (Czech)
A2: 14 | B2: Combat | C2: Adept boje | D2: 10 | E2: CP | F2: Souboj V / Střelba V | G2: Výdrž +5 a Životy +5
A3: 16 | B3: Combat | C3: Expert boje | D3: 10 | E3: CP | F3: Doktrína VII; Adept boje | G3: Výdrž +5 a Životy +5; Umožňuje 1x za den opakovat hod na Zásah, Obranu, Střelbu nebo Vrh (Včetně Kritického neúspěchu)
A4: 18 | B4: Combat | C4: Mistr boje | D4: 20 | E4: CP | F4: Doktrína X; Expert boje | G4: Výdrž +10 a Životy +5; Opakovaný hod na Zásah/Obranu/Střelbu/Vrh nebude spotřebován, pokud vyústí v Kritický úspěch.
A5: 20 | B5: Combat | C5: Akrobatická obrana I | D5: 10 | E5: CP | F5: Akrobacie V; Souboj V / Střelba V | G5: Zvyšuje Kryt o 10% a Úhyb o 10%. Zvyšuje šanci na Kritický úspěch Úhybu o 3%. Zvyšuje hranici úspěchu pro Úhyb na 80%. Umožňuje redukovat přímé magické poškození o 50% při úspěšném versus Testu Úhybu proti Magickému útoku.
A6: 22 | B6: Combat | C6: Akrobatická obrana II | D6: 10 | E6: CP | F6: Akrobatická obrana I | G6: Pokud je vrchní vrstva zbroje Lehká, získá při Úhybu Odklonění +20%
A7: 24 | B7: Combat | C7: Akrobatická obrana III | D7: 10 | E7: CP | F7: Akrobatická obrana II; Akrobacie X | G7: Zvyšuje Úhyb o 10%. Zvyšuje šanci na Kritický úspěch Úhybu o 4%. Ruší hranici úspěchu pro Úhyb.
A8: 26 | B8: Combat | C8: Akrobat I | D8: 0 | E8: CP | F8: Akrobatická obrana I | G8: Pokud je Povalený, může jednou za kolo použít Volnou akci na Test Akrobacie (Velmi těžký), při úspěchu získává 1 Akci. Dodatečně může Testovat Rychlost (Velmi těžký), při úspěchu se nesnižuje Pořadí tahu na 1.
A9: 28 | B9: Combat | C9: Akrobat II | D9: 5 | E9: CP | F9: Akrobat I; Akrobacie: Adept | G9: Má-li být Povalen, může Testovat Akrobacii (-60%), při úspěchu se efektu Povalení vyhne a pohne se o jednu hexu dozadu. Tento pohyb nevyvolá příležitostný útok.
A10: 30 | B10: Combat | C10: Atletická vytrvalost | D10: 20 | E10: CP | F10: Atletika V | G10: Životy +5, Výdrž +10, může 1x za den opakovat hod na soubojový versus Test Síly.
A11: 32 | B11: Combat | C11: Bezpečný krok | D11: 5 | E11: CP | F11: Plížení VIII | G11: Při Pomalém pohybu okolo oponenta může Testovat Plížení (Legendární), při úspěchu nevyvolává Příležitostný útok, při neúspěchu se nemůže bránit.
A12: 34 | B12: Combat | C12: Bijec končetin | D12: 10 | E12: CP | F12: Zbraň VIII | G12: Zásah do rukou, nohou či hlavy způbobuje dodatečné zranění +2d4
A13: 36 | B13: Combat | C13: Bleskové reflexy | D13: 15 | E13: CP | F13: Vnímání 4; Doktrína V | G13: Nepřítel nemá Výhodu na útok za Neviditelnost a útoky na Neviditelný cíl nemají Nevýhodu. Postih za Slepotu je poloviční. Reakce +1
... A392: 831 | B392: Racial | C392: Ochrana nebes | D392: 5 | E392: CP | F392: Thoheth; Víra 5 | G392: Může používat Svatou energii místo Životů.
